Workbook
Name a: #REF!
Name UFPrn20020705094329: #REF!
Name UFPrn20020706083617: #REF!
Name UFPrn20020706091951: #REF!
Name UFPrn20020927135942: #REF!
Name UFPrn20170109093005: #REF!
Name UFPrn20171203132302: #REF!
Name UFPrn20171203133741: #REF!
Name UFPrn20171203133843: #REF!
Name UFPrn20171203164125: #REF!
Name UFPrn20180313163522: #REF!
Name UFPrn20180313164711: #REF!
Name 表头: #REF!
Name 固定资产及累计折旧明细帐: #REF!
Name 固定资产清单: #REF!
Name 合计: #REF!
Name 数量金额总账: #REF!
Name 总: #REF!

Sheet 设定
A1: 所属会计师事务所： | E1: 立信会计师事务所（特殊普通合伙）
A2: 被审计单位： | E2: A公司 | F2: 编制人 | G2: 日期： | H2: 2025.01.04 | I2: 索引号：S6601.01
A3: 会计期间： | B3: 2024.01.01-2024.12.31 | E3: 2024.12.31 | F3: 复核人 | G3: 日期： | H3: 2025.01.10 | I3: 页次：
A4: 数据公司 | E4: A公司

Sheet 审定表
A1: 销售费用审定表
A3: 所属会计师事务所： | E3: =设定!E1 -> 立信会计师事务所（特殊普通合伙）
A4: 被审计单位： | E4: =设定!E2 -> A公司 | F4: =设定!F2 -> 编制人 | G4: 日期： | H4: =设定!H2 -> 2025.01.04 | I4: =设定!I2 -> 索引号：S6601.01
A5: 会计期间： | E5: =设定!E3 -> 2024.12.31 | F5: =设定!F3 -> 复核人 | G5: 日期： | H5: =设定!H3 -> 2025.01.10 | I5: 页次：
A6: 数据公司 | E6: =设定!E2 -> A公司
A7: 公司 | B7: 科目编码 | C7: 底稿科目 | D7: 附注分类 | E7: 本期未审数 | F7: 重分类调整 | G7: 审计调整 | H7: 调整索引 | I7: 审定数
J8: 附注项目（未填为其他）
I9: =E9+F9+G9 -> 0
I10: =E10+F10+G10 -> 0 | J10: 工资薪金
I11: =E11+F11+G11 -> 0
I12: =E12+F12+G12 -> 0 | J12: 办公费
I13: =E13+F13+G13 -> 0 | J13: 其他
I14: =E14+F14+G14 -> 0 | J14: 招待费
I15: =E15+F15+G15 -> 0
I16: =E16+F16+G16 -> 0
I17: =E17+F17+G17 -> 0
I18: =E18+F18+G18 -> 0
I19: =E19+F19+G19 -> 0
I20: =E20+F20+G20 -> 0
I21: =E21+F21+G21 -> 0 | J21: 差旅费
I22: =E22+F22+G22 -> 0 | K22: 上海 | L22: 重庆
I23: =E23+F23+G23 -> 0
I24: =E24+F24+G24 -> 0 | J24: 运输费
I25: =E25+F25+G25 -> 0
I26: =E26+F26+G26 -> 0
I27: =E27+F27+G27 -> 0
I28: =E28+F28+G28 -> 0
I29: =E29+F29+G29 -> 0 | J29: 差旅费
I30: =E30+F30+G30 -> 0 | K30: 上海 | L30: 重庆
I31: =E31+F31+G31 -> 0
I32: =E32+F32+G32 -> 0 | J32: 运输费
I33: =E33+F33+G33 -> 0
I34: =E34+F34+G34 -> 0
I35: =E35+F35+G35 -> 0
I36: =E36+F36+G36 -> 0
I37: =E37+F37+G37 -> 0
I38: =E38+F38+G38 -> 0
I39: =E39+F39+G39 -> 0
I40: =E40+F40+G40 -> 0
I41: =E41+F41+G41 -> 0
...

Sheet 同期比较
A1: 销售费用本期与上年同期比较表
A3: 所属会计师事务所： | C3: =设定!E1 -> 立信会计师事务所（特殊普通合伙）
A4: 被审计单位： | C4: =设定!E2 -> A公司 | F4: 审核员： | G4: =设定!H2 -> 2025.01.04 | H4: 日期： | I4: =设定!H2 -> 2025.01.04 | J4: 索引号： | K4: S6601.03
A5: 审查项目： | C5: 销售费用 | D5: 会计期间： | E5: =设定!B3 -> 2024.01.01-2024.12.31 | F5: 复核员： | G5: =设定!F3 -> 复核人 | H5: 日期： | I5: =设定!H3 -> 2025.01.10 | J5: 页次：
A7: 公司 | B7: 项目 | C7: 本期审定发生额 | E7: 上年同期审定额 | G7: 增减额 | H7: 增减比例 | I7: 变动分析
C8: 金额 | D8: 比重 | E8: 金额 | F8: 比重
D9: =IF($C$46=0,0,C9/$C$46) -> 0 | F9: =IF($E$46=0,0,E9/$E$46) -> 0 | G9: =C9-E9 -> 0 | H9: =IF(E9=0,0,G9/E9) -> 0
D10: =IF($C$46=0,0,C10/$C$46) -> 0 | F10: =IF($E$46=0,0,E10/$E$46) -> 0 | G10: =C10-E10 -> 0 | H10: =IF(E10=0,0,G10/E10) -> 0
D11: =IF($C$46=0,0,C11/$C$46) -> 0 | F11: =IF($E$46=0,0,E11/$E$46) -> 0 | G11: =C11-E11 -> 0 | H11: =IF(E11=0,0,G11/E11) -> 0
D12: =IF($C$46=0,0,C12/$C$46) -> 0 | F12: =IF($E$46=0,0,E12/$E$46) -> 0 | G12: =C12-E12 -> 0 | H12: =IF(E12=0,0,G12/E12) -> 0
D13: =IF($C$46=0,0,C13/$C$46) -> 0 | F13: =IF($E$46=0,0,E13/$E$46) -> 0 | G13: =C13-E13 -> 0 | H13: =IF(E13=0,0,G13/E13) -> 0
D14: =IF($C$46=0,0,C14/$C$46) -> 0 | F14: =IF($E$46=0,0,E14/$E$46) -> 0 | G14: =C14-E14 -> 0 | H14: =IF(E14=0,0,G14/E14) -> 0
D15: =IF($C$46=0,0,C15/$C$46) -> 0 | F15: =IF($E$46=0,0,E15/$E$46) -> 0 | G15: =C15-E15 -> 0 | H15: =IF(E15=0,0,G15/E15) -> 0
D16: =IF($C$46=0,0,C16/$C$46) -> 0 | F16: =IF($E$46=0,0,E16/$E$46) -> 0 | G16: =C16-E16 -> 0 | H16: =IF(E16=0,0,G16/E16) -> 0
D17: =IF($C$46=0,0,C17/$C$46) -> 0 | F17: =IF($E$46=0,0,E17/$E$46) -> 0 | G17: =C17-E17 -> 0 | H17: =IF(E17=0,0,G17/E17) -> 0
D18: =IF($C$46=0,0,C18/$C$46) -> 0 | F18: =IF($E$46=0,0,E18/$E$46) -> 0 | G18: =C18-E18 -> 0 | H18: =IF(E18=0,0,G18/E18) -> 0
D19: =IF($C$46=0,0,C19/$C$46) -> 0 | F19: =IF($E$46=0,0,E19/$E$46) -> 0 | G19: =C19-E19 -> 0 | H19: =IF(E19=0,0,G19/E19) -> 0
D20: =IF($C$46=0,0,C20/$C$46) -> 0 | F20: =IF($E$46=0,0,E20/$E$46) -> 0 | G20: =C20-E20 -> 0 | H20: =IF(E20=0,0,G20/E20) -> 0
... D45: =IF($C$46=0,0,C45/$C$46) -> 0 | F45: =IF($E$46=0,0,E45/$E$46) -> 0 | G45: =C45-E45 -> 0 | H45: =IF(E45=0,0,G45/E45) -> 0
B46: 合计 | C46: =SUM(C11:C45) -> 0 | D46: =IF($C$46=0,0,C46/$C$46) -> 0 | E46: =SUM(E9:E45) -> 0 | F46: =IF($E$46=0,0,E46/$E$46) -> 0 | G46: =SUM(G9:G45) -> 0 | H46: =IF(E46=0,0,G46/E46) -> 0
A48: 审计结论：可以确认。
